<?xml version="1.0" encoding="utf-8"?>
<robot
    xmlns="http://www.ros.org/wiki/urdf"
    name="premium">
  <link name="base" >
    <visual>
      <origin xyz="-0.044 0 0.05" />
      <geometry>
        <box size="0.254 0.33 0.1" />
      </geometry>
    </visual>
  </link>
  <link name="torso" >
    <visual>
      <origin xyz="0 0 0.005" />
      <geometry>
	<cylinder radius="0.086" length="0.01" />
      </geometry>
    </visual>
  </link>
  <link name="upper_arm" >
    <visual>
      <origin xyz="0.10475 0 0" rpy="0 1.5707 0" />
      <geometry>
	<cylinder radius="0.005" length="0.20955" />
      </geometry>
    </visual>
  </link>
  <link name="lower_arm" >
    <visual>
      <origin xyz="0.10475 0 0" rpy="0 1.5707 0"  />
      <geometry>
	<cylinder radius="0.005" length="0.20955" />
      </geometry>
    </visual>
  </link>
  <link name="wrist1" />
  <link name="wrist2" />
  <link name="stylus" >
    <visual>
      <origin xyz="0.074 0 0" rpy="0 1.5707 0" />
      <geometry>
	<cylinder radius="0.011" length="0.148" />
      </geometry>
    </visual>
  </link>
  <link name="stylus_end" />
  

  <joint name="waist" type="continuous" >
    <parent link="base" />
    <child link="torso" />
    <origin xyz="0 0 0.17" rpy="0 0 0" />
    <axis xyz="0 0 1" />
  </joint>

  <joint name="shoulder" type="continuous" >
    <parent link="torso" />
    <child link="upper_arm" />
    <origin xyz="0 0 0.1" rpy="0 0 0" />
    <axis xyz="0 -1 0" />
  </joint>

  <joint name="elbow" type="continuous" >
    <parent link="upper_arm" />
    <child link="lower_arm" />
    <origin xyz="0.20955 0 0" rpy="0 1.5707 0" />
    <axis xyz="0 -1 0" />
  </joint>
  
  <joint name="wrist1" type="continuous" >
    <parent link="lower_arm" />
    <child link="wrist1" />
    <origin xyz="0.20955 0 0" />
    <axis xyz="1 0 0" />
  </joint>
  
  <joint name="wrist2" type="continuous" >
    <parent link="wrist1" />
    <child link="wrist2" />
    <origin xyz="0.0 0 0" rpy="0 1.5707 0" />
    <axis xyz="0 -1 0" />
  </joint>
  
  <joint name="wrist3" type="continuous" >
    <parent link="wrist2" />
    <child link="stylus" />
    <origin xyz="0.0 0 0" />
    <axis xyz="1 0 0" />
  </joint>
  
    <joint name="stylus" type="fixed" >
    <parent link="stylus" />
    <child link="stylus_end" />
    <origin xyz="0.1487 0 0" />
    <axis xyz="1 0 0" />
  </joint>
</robot>

